Workbook

Sheet 1. Overview
A1: Goal-Based Portfolio Planner - Methodology & Calculation Backend
A3: This workbook is a live, formula-driven backend for the planner app - not documentation. It computes the same return/volatility/correlation figures, the same solved portfolio weights, and the same worked-example numbers that the app shows, from the same underlying assumptions, so the app, the assumptions and this workbook always agree.
A5: GLOBAL RULES
A6: - All rupee figures are shown with Indian (lakh/crore) comma grouping, e.g. 12,50,000.
A7: - All income figures are MONTHLY, in INR.
A9: SHEETS IN THIS WORKBOOK
A10: 2. Market Data - the 120-month (10-year) representative return series for each asset class, and live formulas computing CAGR, annualised volatility and the correlation matrix from it.
A11: 3. Assumptions - expected return & volatility per asset (pulled live from sheet 2), goal-type inflation rates, income bands, and the city/housing/vehicle expense-estimation table.
A12: 4. Risk & Portfolio Rules - risk-aversion (lambda) per profile, equity caps by time horizon, per-asset concentration caps, and the risk-scoring rules.
A13: 5. MVO Solver (worked) - the covariance matrix built from sheet 2+3, a SOLVED Mean-Variance-Optimal portfolio for one case (Moderate profile, Medium-term horizon), and a live-formula panel proving its return/risk/objective value versus naive alternative portfolios.
A14: 6. Portfolio Construction - the solved MVO weights for all 9 (time-horizon x risk-profile) combinations the app uses, plus the existing+new-money portfolio-combination formulas.
A15: 7. Worked Example - one full client scenario, computed end-to-end with live formulas, matching the app's output for the identical inputs.
... A20: EQUITY RETURN ASSUMPTIONS UPDATED WITH REAL DATA (2026-10-21): Large/Mid/Small cap expected-return figures now use the official NSE Indices factsheet since-inception Price Return CAGR for Nifty 100 / Nifty Midcap 150 / Nifty Smallcap 250 (14.26% / 15.42% / 14.32% respectively, factsheets as-of 30-Sep-2026) in place of the earlier calibrated placeholders. Volatility and correlation, and all figures for Liquid/Debt/Gold/Real Estate, remain documented calibrated assumptions - see config.py and sheet 3 for exact sourcing and the reasons those could not also be pulled from public data. A consequence of using the real figures: Small Cap's risk-adjusted profile now trails Large/Mid cap over this window, so the optimiser legitimately allocates it 0% in most risk-profile/horizon combinations - this is the model correctly reading real data, not an error.

Sheet 2. Market Data
A1: 10-Year (120-month) Representative Monthly Returns, by Asset Class
A2: A calibrated, reproducible representative series (seeded random generation matched exactly to commonly reported 10-year return/volatility/correlation statistics for each index/instrument - this sandbox has no certified line-by-line NSE/AMFI price history to cite). Large/Mid/Small cap use the PRICE RETURN version of the Nifty 100 / Nifty Midcap 150 / Nifty Smallcap 250 indices (not TRI). Replace this block with real index/fund NAV history if available - every formula below recalculates automatically.
A4: Month | B4: Liquid Fund | C4: Debt Fund | D4: Gold | E4: Real Estate | F4: Large Cap Mutual Fund | G4: Mid Cap Mutual Fund | H4: Small Cap Mutual Fund
A5: 2015-10 | B5: 0.008994 | C5: -0.006511 | D5: 0.008092 | E5: 0.016913 | F5: 0.031719 | G5: 0.041104 | H5: 0.041189
A6: 2015-11 | B6: 0.004796 | C6: 0.014491 | D6: -0.076714 | E6: -0.011268 | F6: -0.017867 | G6: -0.046361 | H6: -0.070253
A7: 2015-12 | B7: 0.009175 | C7: 0.009656 | D7: 0.027279 | E7: 0.036365 | F7: 0.028146 | G7: 0.006435 | H7: -0.001187
A8: 2016-01 | B8: -0.001576 | C8: 0.003589 | D8: 0.020619 | E8: 0.022069 | F8: 0.003418 | G8: 0.014915 | H8: 0.029752
A9: 2016-02 | B9: 0.015164 | C9: 0.017869 | D9: -0.029872 | E9: -0.031162 | F9: 0.024175 | G9: 0.050338 | H9: 0.06947
A10: 2016-03 | B10: 0.005654 | C10: 0.00788 | D10: 0.178423 | E10: 0.05788 | F10: -0.088074 | G10: -0.142127 | H10: -0.178034
A11: 2016-04 | B11: 0.005888 | C11: 0.019383 | D11: 0.004661 | E11: -0.024975 | F11: 0.025222 | G11: 0.027892 | H11: 0.043957
A12: 2016-05 | B12: 0.003868 | C12: 0.012138 | D12: 0.041817 | E12: 0.064735 | F12: -0.009679 | G12: 0.010856 | H12: 0.011156
A13: 2016-06 | B13: -0.001893 | C13: 0.000905 | D13: 0.141889 | E13: 0.071773 | F13: 0.00859 | G13: 0.009614 | H13: 0.016163
A14: 2016-07 | B14: 0.008396 | C14: 0.013917 | D14: 0.001088 | E14: 0.032823 | F14: -0.033583 | G14: -0.037561 | H14: -0.052954
A15: 2016-08 | B15: -0.00375 | C15: 0.00834 | D15: 0.04562 | E15: 0.028779 | F15: 0.082481 | G15: 0.081389 | H15: 0.085374
A16: 2016-09 | B16: 0.005815 | C16: -0.008299 | D16: -0.023562 | E16: 0.014101 | F16: 0.126054 | G16: 0.140579 | H16: 0.156977
... A124: 2025-09 | B124: 0.002333 | C124: 0.01055 | D124: 0.070273 | E124: 0.03266 | F124: 0.010762 | G124: 0.0344 | H124: 0.038266
A126: CAGR (annualised) | B126: =EXP(SUMPRODUCT(LN(1+B5:B124)))^(12/120)-1 -> 0.055239832 | C126: =EXP(SUMPRODUCT(LN(1+C5:C124)))^(12/120)-1 -> 0.070752542 | D126: =EXP(SUMPRODUCT(LN(1+D5:D124)))^(12/120)-1 -> 0.096267592 | E126: =EXP(SUMPRODUCT(LN(1+E5:E124)))^(12/120)-1 -> 0.12128234 | F126: =EXP(SUMPRODUCT(LN(1+F5:F124)))^(12/120)-1 -> 0.14066184 | G126: =EXP(SUMPRODUCT(LN(1+G5:G124)))^(12/120)-1 -> 0.1453984 | H126: =EXP(SUMPRODUCT(LN(1+H5:H124)))^(12/120)-1 -> 0.12246789
A127: Annualised volatility | B127: =STDEV(B5:B124)*SQRT(12) -> 0.014999964 | C127: =STDEV(C5:C124)*SQRT(12) -> 0.030000065 | D127: =STDEV(D5:D124)*SQRT(12) -> 0.21500002 | E127: =STDEV(E5:E124)*SQRT(12) -> 0.089999914 | F127: =STDEV(F5:F124)*SQRT(12) -> 0.14499998 | G127: =STDEV(G5:G124)*SQRT(12) -> 0.19000006 | H127: =STDEV(H5:H124)*SQRT(12) -> 0.23500018
A129: Correlation matrix (raw, from the 120-month series)
B130: Liquid Fund | C130: Debt Fund | D130: Gold | E130: Real Estate | F130: Large Cap Mutual Fund | G130: Mid Cap Mutual Fund | H130: Small Cap Mutual Fund
A131: Liquid Fund | B131: =CORREL(B5:B124,B5:B124) -> 1 | C131: =CORREL(B5:B124,C5:C124) -> 0.26869191 | D131: =CORREL(B5:B124,D5:D124) -> 0.099786819 | E131: =CORREL(B5:B124,E5:E124) -> 2.0600119e-06 | F131: =CORREL(B5:B124,F5:F124) -> -2.234364e-06 | G131: =CORREL(B5:B124,G5:G124) -> -5.6981999e-06 | H131: =CORREL(B5:B124,H5:H124) -> -6.6022727e-06
A132: Debt Fund | B132: =CORREL(C5:C124,B5:B124) -> 0.26869191 | C132: =CORREL(C5:C124,C5:C124) -> 1 | D132: =CORREL(C5:C124,D5:D124) -> 0.2692651 | E132: =CORREL(C5:C124,E5:E124) -> -4.0695758e-06 | F132: =CORREL(C5:C124,F5:F124) -> -1.5193009e-06 | G132: =CORREL(C5:C124,G5:G124) -> -2.323215e-06 | H132: =CORREL(C5:C124,H5:H124) -> -2.2361025e-06
A133: Gold | B133: =CORREL(D5:D124,B5:B124) -> 0.099786819 | C133: =CORREL(D5:D124,C5:C124) -> 0.2692651 | D133: =CORREL(D5:D124,D5:D124) -> 1 | E133: =CORREL(D5:D124,E5:E124) -> 0.56353414 | F133: =CORREL(D5:D124,F5:F124) -> -7.3551933e-07 | G133: =CORREL(D5:D124,G5:G124) -> 1.844369e-07 | H133: =CORREL(D5:D124,H5:H124) -> 1.784841e-07
A134: Real Estate | B134: =CORREL(E5:E124,B5:B124) -> 2.0600119e-06 | C134: =CORREL(E5:E124,C5:C124) -> -4.0695758e-06 | D134: =CORREL(E5:E124,D5:D124) -> 0.56353414 | E134: =CORREL(E5:E124,E5:E124) -> 1 | F134: =CORREL(E5:E124,F5:F124) -> 0.15333157 | G134: =CORREL(E5:E124,G5:G124) -> 0.15333278 | H134: =CORREL(E5:E124,H5:H124) -> 0.15333225
A135: Large Cap Mutual Fund | B135: =CORREL(F5:F124,B5:B124) -> -2.234364e-06 | C135: =CORREL(F5:F124,C5:C124) -> -1.5193009e-06 | D135: =CORREL(F5:F124,D5:D124) -> -7.3551933e-07 | E135: =CORREL(F5:F124,E5:E124) -> 0.15333157 | F135: =CORREL(F5:F124,F5:F124) -> 1 | G135: =CORREL(F5:F124,G5:G124) -> 0.94543483 | H135: =CORREL(F5:F124,H5:H124) -> 0.92179675
A136: Mid Cap Mutual Fund | B136: =CORREL(G5:G124,B5:B124) -> -5.6981999e-06 | C136: =CORREL(G5:G124,C5:C124) -> -2.323215e-06 | D136: =CORREL(G5:G124,D5:D124) -> 1.844369e-07 | E136: =CORREL(G5:G124,E5:E124) -> 0.15333278 | F136: =CORREL(G5:G124,F5:F124) -> 0.94543483 | G136: =CORREL(G5:G124,G5:G124) -> 1 | H136: =CORREL(G5:G124,H5:H124) -> 0.9911519
A137: Small Cap Mutual Fund | B137: =CORREL(H5:H124,B5:B124) -> -6.6022727e-06 | C137: =CORREL(H5:H124,C5:C124) -> -2.2361025e-06 | D137: =CORREL(H5:H124,D5:D124) -> 1.784841e-07 | E137: =CORREL(H5:H124,E5:E124) -> 0.15333225 | F137: =CORREL(H5:H124,F5:F124) -> 0.92179675 | G137: =CORREL(H5:H124,G5:G124) -> 0.9911519 | H137: =CORREL(H5:H124,H5:H124) -> 1

Sheet 3. Assumptions
A1: Assumptions
A3: Asset-class return & volatility (calculated from '2. Market Data', not hand-typed)
A4: Asset | B4: Index / instrument | C4: Expected return (annual) | D4: Volatility (annual)
A5: Liquid Fund | B5: Overnight / liquid-fund category (proxy for a money-market instrument) | C5: ='2. Market Data'!B126 -> 0.055239832 | D5: ='2. Market Data'!B127 -> 0.014999964
A6: Debt Fund | B6: Short-duration debt-fund category (proxy for a diversified bond fund) | C6: ='2. Market Data'!C126 -> 0.070752542 | D6: ='2. Market Data'!C127 -> 0.030000065
A7: Gold | B7: Domestic gold price (INR) | C7: ='2. Market Data'!D126 -> 0.096267592 | D7: ='2. Market Data'!D127 -> 0.21500002
A8: Real Estate | B8: Residential real-estate price index (representative, India) | C8: ='2. Market Data'!E126 -> 0.12128234 | D8: ='2. Market Data'!E127 -> 0.089999914
A9: Large Cap Mutual Fund | B9: Nifty 100 - PRICE RETURN index (not TRI) | C9: ='2. Market Data'!F126 -> 0.14066184 | D9: ='2. Market Data'!F127 -> 0.14499998
A10: Mid Cap Mutual Fund | B10: Nifty Midcap 150 - PRICE RETURN index (not TRI) | C10: ='2. Market Data'!G126 -> 0.1453984 | D10: ='2. Market Data'!G127 -> 0.19000006
A11: Small Cap Mutual Fund | B11: Nifty Smallcap 250 - PRICE RETURN index (not TRI) | C11: ='2. Market Data'!H126 -> 0.12246789 | D11: ='2. Market Data'!H127 -> 0.23500018
A14: Goal-type inflation assumptions
A15: Goal type | B15: Assumed inflation (annual)
A16: Vacation | B16: 0.06
A17: Housing | B17: 0.06
A18: Healthcare | B18: 0.09
A19: Education | B19: 0.08
A20: Marriage | B20: 0.07
A21: Others | B21: 0.05
A22: 'Others' uses the general inflation rate. Education, healthcare and marriage inflate faster than general CPI, which is the commonly used planning convention in India.
A24: General planning assumptions
A25: General inflation (CPI) | B25: 0.05
A26: Planning safety margin (added to required-return target) | B26: 0.01
A27: Risk-free rate (used for Sharpe ratio) | B27: 0.053
A28: Retirement corpus multiple (x annual expenses) | B28: 25
A29: Correlation shrinkage (toward average off-diagonal correlation) | B29: 0.35
A30: Monte Carlo simulation paths | B30: 2000
A32: Income bands (representative monthly income, INR)
A33: Band | B33: Representative monthly income
A34: Below Rs 50,000 | B34: 35000
A35: Rs 50,000 - 1,00,000 | B35: 75000
A36: Rs 1,00,000 - 2,00,000 | B36: 150000
A37: Rs 2,00,000 - 3,00,000 | B37: 250000
A38: Rs 3,00,000 - 5,00,000 | B38: 400000
A39: Rs 5,00,000 - 10,00,000 | B39: 750000
A40: Rs 10,00,000 - 15,00,000 | B40: 1250000
A41: Rs 15,00,000 - 25,00,000 | B41: 2000000
A42: Rs 25,00,000 - 50,00,000 | B42: 3750000
A43: Above Rs 50,00,000 | B43: 6500000
A45: Base expense ratio by income band (before adjustments)
A46: Band | B46: Base expense ratio
...

Sheet 4. Risk & Portfolio Rules
A1: Risk Scoring & Portfolio-Construction Rules
A3: Risk aversion (lambda) by recommended profile - used in the MVO objective
A4: Profile | B4: Conservative | C4: Moderate | D4: Aggressive
A5: Lambda (risk aversion) | B5: 9 | C5: 3.5 | D5: 1.2
A7: Maximum equity exposure by time horizon
A8: Horizon bucket | B8: Max equity (Large+Mid+Small cap)
A9: Short | B9: 0.15
A10: Medium | B10: 0.55
A11: Long | B11: 1
A12: Short <= 3 years, Medium 3-7 years, Long > 7 years (config.SHORT_MAX_YEARS / MEDIUM_MAX_YEARS).
A14: Per-asset concentration caps in the MVO solve
A15: Asset | B15: Max weight
A16: Liquid Fund | B16: 1
A17: Debt Fund | B17: 1
A18: Gold | B18: 0.2
A19: Real Estate | B19: 0.2
A20: Large Cap Mutual Fund | B20: 0.35
A21: Mid Cap Mutual Fund | B21: 0.35
A22: Small Cap Mutual Fund | B22: 0.3
A23: Liquid Fund and Debt Fund are uncapped (100%); every equity sub-asset (Large/Mid/Small cap) carries its own cap so the optimiser cannot crowd one market-cap segment out to 0% just because it has a marginally better risk-adjusted profile under high correlation.
A25: Risk-score rule
A26: Score (1-10) = MIN(Willingness, Capacity) - never take more risk than the client is comfortable
A27: with, or more than their situation can actually afford.
A29: Willingness = 40% x stated appetite (Low=3, Moderate=6, High=9) + 60% x average of 3 scenario
A30: quiz answers (each scored 2 / 6 / 10) - behaviour-based answers weigh more than a self-label.
A32: Capacity = average of 5 points, each scored out of 10:
A33: - Age points: <=30 -> 9, <=40 -> 7, <=50 -> 5, <=60 -> 3, else 2
A34: - Dependents points: 0 -> 9, 1 -> 7, 2 -> 5, 3+ -> 3
A35: - Horizon points: clamp(1 + 0.6 x money-weighted average years to goals, 1, 10)
A36: - Emergency-fund points: 2 + 7 x min(1, current emergency savings / recommended target)
A37: (this affects ONLY the capacity score - it never reduces the amount invested; see note below)
... A43: The emergency fund shortfall/target is shown to the client as a recommendation. It is used ONLY in the capacity score above (as a measure of financial cushion). It is NEVER subtracted from the investable amount, and never enters the portfolio or corpus calculations anywhere in this workbook or in the app.

Sheet 5. MVO Solver (worked)
A1: Mean-Variance Optimization - worked case: Moderate profile, Medium-term horizon (5 years)
A2: Objective: maximise w'mu - 0.5 x lambda x w'(Sigma)w subject to: weights sum to 100%, no negative weights, equity (Large+Mid+Small cap) <= the horizon's cap, and each asset's own cap (sheet 4). Solved with scipy.optimize.minimize (SLSQP) in the same Python engine (allocation.py) that powers the app - Excel/LibreOffice cannot run this constrained optimisation headlessly, so the solved WEIGHTS below are a documented input; every number below them is a LIVE FORMULA from those weights, so you can verify the arithmetic and see that they beat naive alternatives.
A4: Shrinkage-adjusted correlation matrix
A5: Shrinkage factor (alpha, from sheet 3): ='3. Assumptions'!B29
A6: Average off-diagonal raw correlation | B6: =AVERAGE('2. Market Data'!C131,'2. Market Data'!D131,'2. Market Data'!E131,'2. Market Data'!F131,'2. Market Data'!G131,'2. Market Data'!H131,'2. Market Data'!B132,'2. Market Data'!D132,'2. Market Data'!E132,'2. Market Data'!F132,'2. Market Data'!G132,'2. Market Data'!H132,'2. Market Data'!B133,'2. Market Data'!C133,'2. Market Data'!E133,'2. Market Data'!F133,'2. Market Data'!G133,'2. Market Data'!H133,'2. Market Data'!B134,'2. Market Data'!C134,'2. Market Data'!D134,'2. Market Data'!F134,'2. Market Data'!G134,'2. Market Data'!H134,'2. Market Data'!B135,'2. Market Data'!C135,'2. Market Data'!D135,'2. Market Data'!E135,'2. Market Data'!G135,'2. Market Data'!H135,'2. Market Data'!B136,'2. Market Data'!C136,'2. Market Data'!D136,'2. Market Data'!E136,'2. Market Data'!F136,'2. Market Data'!H136,'2. Market Data'!B137,'2. Market Data'!C137,'2. Market Data'!D137,'2. Market Data'!E137,'2. Market Data'!F137,'2. Market Data'!G137) -> 0.21522072
B8: Liquid Fund | C8: Debt Fund | D8: Gold | E8: Real Estate | F8: Large Cap Mutual Fund | G8: Mid Cap Mutual Fund | H8: Small Cap Mutual Fund
A9: Liquid Fund | B9: 1 | C9: =(1-$B$5)*'2. Market Data'!C131+$B$5*$B$6 -> 0.26869191 | D9: =(1-$B$5)*'2. Market Data'!D131+$B$5*$B$6 -> 0.099786819 | E9: =(1-$B$5)*'2. Market Data'!E131+$B$5*$B$6 -> 2.0600119e-06 | F9: =(1-$B$5)*'2. Market Data'!F131+$B$5*$B$6 -> -2.234364e-06 | G9: =(1-$B$5)*'2. Market Data'!G131+$B$5*$B$6 -> -5.6981999e-06 | H9: =(1-$B$5)*'2. Market Data'!H131+$B$5*$B$6 -> -6.6022727e-06
A10: Debt Fund | B10: =(1-$B$5)*'2. Market Data'!B132+$B$5*$B$6 -> 0.26869191 | C10: 1 | D10: =(1-$B$5)*'2. Market Data'!D132+$B$5*$B$6 -> 0.2692651 | E10: =(1-$B$5)*'2. Market Data'!E132+$B$5*$B$6 -> -4.0695758e-06 | F10: =(1-$B$5)*'2. Market Data'!F132+$B$5*$B$6 -> -1.5193009e-06 | G10: =(1-$B$5)*'2. Market Data'!G132+$B$5*$B$6 -> -2.323215e-06 | H10: =(1-$B$5)*'2. Market Data'!H132+$B$5*$B$6 -> -2.2361025e-06
A11: Gold | B11: =(1-$B$5)*'2. Market Data'!B133+$B$5*$B$6 -> 0.099786819 | C11: =(1-$B$5)*'2. Market Data'!C133+$B$5*$B$6 -> 0.2692651 | D11: 1 | E11: =(1-$B$5)*'2. Market Data'!E133+$B$5*$B$6 -> 0.56353414 | F11: =(1-$B$5)*'2. Market Data'!F133+$B$5*$B$6 -> -7.3551933e-07 | G11: =(1-$B$5)*'2. Market Data'!G133+$B$5*$B$6 -> 1.844369e-07 | H11: =(1-$B$5)*'2. Market Data'!H133+$B$5*$B$6 -> 1.784841e-07
A12: Real Estate | B12: =(1-$B$5)*'2. Market Data'!B134+$B$5*$B$6 -> 2.0600119e-06 | C12: =(1-$B$5)*'2. Market Data'!C134+$B$5*$B$6 -> -4.0695758e-06 | D12: =(1-$B$5)*'2. Market Data'!D134+$B$5*$B$6 -> 0.56353414 | E12: 1 | F12: =(1-$B$5)*'2. Market Data'!F134+$B$5*$B$6 -> 0.15333157 | G12: =(1-$B$5)*'2. Market Data'!G134+$B$5*$B$6 -> 0.15333278 | H12: =(1-$B$5)*'2. Market Data'!H134+$B$5*$B$6 -> 0.15333225
A13: Large Cap Mutual Fund | B13: =(1-$B$5)*'2. Market Data'!B135+$B$5*$B$6 -> -2.234364e-06 | C13: =(1-$B$5)*'2. Market Data'!C135+$B$5*$B$6 -> -1.5193009e-06 | D13: =(1-$B$5)*'2. Market Data'!D135+$B$5*$B$6 -> -7.3551933e-07 | E13: =(1-$B$5)*'2. Market Data'!E135+$B$5*$B$6 -> 0.15333157 | F13: 1 | G13: =(1-$B$5)*'2. Market Data'!G135+$B$5*$B$6 -> 0.94543483 | H13: =(1-$B$5)*'2. Market Data'!H135+$B$5*$B$6 -> 0.92179675
A14: Mid Cap Mutual Fund | B14: =(1-$B$5)*'2. Market Data'!B136+$B$5*$B$6 -> -5.6981999e-06 | C14: =(1-$B$5)*'2. Market Data'!C136+$B$5*$B$6 -> -2.323215e-06 | D14: =(1-$B$5)*'2. Market Data'!D136+$B$5*$B$6 -> 1.844369e-07 | E14: =(1-$B$5)*'2. Market Data'!E136+$B$5*$B$6 -> 0.15333278 | F14: =(1-$B$5)*'2. Market Data'!F136+$B$5*$B$6 -> 0.94543483 | G14: 1 | H14: =(1-$B$5)*'2. Market Data'!H136+$B$5*$B$6 -> 0.9911519
A15: Small Cap Mutual Fund | B15: =(1-$B$5)*'2. Market Data'!B137+$B$5*$B$6 -> -6.6022727e-06 | C15: =(1-$B$5)*'2. Market Data'!C137+$B$5*$B$6 -> -2.2361025e-06 | D15: =(1-$B$5)*'2. Market Data'!D137+$B$5*$B$6 -> 1.784841e-07 | E15: =(1-$B$5)*'2. Market Data'!E137+$B$5*$B$6 -> 0.15333225 | F15: =(1-$B$5)*'2. Market Data'!F137+$B$5*$B$6 -> 0.92179675 | G15: =(1-$B$5)*'2. Market Data'!G137+$B$5*$B$6 -> 0.9911519 | H15: 1
A17: Covariance matrix (= vol_i x vol_j x shrunk-corr_ij)
B18: Liquid Fund | C18: Debt Fund | D18: Gold | E18: Real Estate | F18: Large Cap Mutual Fund | G18: Mid Cap Mutual Fund | H18: Small Cap Mutual Fund
A19: Liquid Fund | B19: ='3. Assumptions'!D5*'3. Assumptions'!D5*B9 -> 0.00022499891 | C19: ='3. Assumptions'!D5*'3. Assumptions'!D6*C9 -> 0.00012091133 | D19: ='3. Assumptions'!D5*'3. Assumptions'!D7*D9 -> 0.00032181174 | E19: ='3. Assumptions'!D5*'3. Assumptions'!D8*E9 -> 2.7810067e-09 | F19: ='3. Assumptions'!D5*'3. Assumptions'!D9*F9 -> -4.8597294e-09 | G19: ='3. Assumptions'!D5*'3. Assumptions'!D10*G9 -> -1.6239835e-08 | H19: ='3. Assumptions'!D5*'3. Assumptions'!D11*H9 -> -2.3272973e-08
A20: Debt Fund | B20: ='3. Assumptions'!D6*'3. Assumptions'!D5*B10 -> 0.00012091133 | C20: ='3. Assumptions'!D6*'3. Assumptions'!D6*C10 -> 0.00090000389 | D20: ='3. Assumptions'!D6*'3. Assumptions'!D7*D10 -> 0.0017367638 | E20: ='3. Assumptions'!D6*'3. Assumptions'!D8*E10 -> -1.0987868e-08 | F20: ='3. Assumptions'!D6*'3. Assumptions'!D9*F10 -> -6.6089723e-09 | G20: ='3. Assumptions'!D6*'3. Assumptions'!D10*G10 -> -1.3242358e-08 | H20: ='3. Assumptions'!D6*'3. Assumptions'!D11*H10 -> -1.5764569e-08
A21: Gold | B21: ='3. Assumptions'!D7*'3. Assumptions'!D5*B11 -> 0.00032181174 | C21: ='3. Assumptions'!D7*'3. Assumptions'!D6*C11 -> 0.0017367638 | D21: ='3. Assumptions'!D7*'3. Assumptions'!D7*D11 -> 0.046225008 | E21: ='3. Assumptions'!D7*'3. Assumptions'!D8*E11 -> 0.010904376 | F21: ='3. Assumptions'!D7*'3. Assumptions'!D9*F11 -> -2.2929814e-08 | G21: ='3. Assumptions'!D7*'3. Assumptions'!D10*G11 -> 7.5342504e-09 | H21: ='3. Assumptions'!D7*'3. Assumptions'!D11*H11 -> 9.0179168e-09
A22: Real Estate | B22: ='3. Assumptions'!D8*'3. Assumptions'!D5*B12 -> 2.7810067e-09 | C22: ='3. Assumptions'!D8*'3. Assumptions'!D6*C12 -> -1.0987868e-08 | D22: ='3. Assumptions'!D8*'3. Assumptions'!D7*D12 -> 0.010904376 | E22: ='3. Assumptions'!D8*'3. Assumptions'!D8*E12 -> 0.0080999845 | F22: ='3. Assumptions'!D8*'3. Assumptions'!D9*F12 -> 0.0020009748 | G22: ='3. Assumptions'!D8*'3. Assumptions'!D10*G12 -> 0.0026219889 | H22: ='3. Assumptions'!D8*'3. Assumptions'!D11*H12 -> 0.0032429765
A23: Large Cap Mutual Fund | B23: ='3. Assumptions'!D9*'3. Assumptions'!D5*B13 -> -4.8597294e-09 | C23: ='3. Assumptions'!D9*'3. Assumptions'!D6*C13 -> -6.6089723e-09 | D23: ='3. Assumptions'!D9*'3. Assumptions'!D7*D13 -> -2.2929814e-08 | E23: ='3. Assumptions'!D9*'3. Assumptions'!D8*E13 -> 0.0020009748 | F23: ='3. Assumptions'!D9*'3. Assumptions'!D9*F13 -> 0.021024995 | G23: ='3. Assumptions'!D9*'3. Assumptions'!D10*G13 -> 0.026046734 | H23: ='3. Assumptions'!D9*'3. Assumptions'!D11*H13 -> 0.031410245
A24: Mid Cap Mutual Fund | B24: ='3. Assumptions'!D10*'3. Assumptions'!D5*B14 -> -1.6239835e-08 | C24: ='3. Assumptions'!D10*'3. Assumptions'!D6*C14 -> -1.3242358e-08 | D24: ='3. Assumptions'!D10*'3. Assumptions'!D7*D14 -> 7.5342504e-09 | E24: ='3. Assumptions'!D10*'3. Assumptions'!D8*E14 -> 0.0026219889 | F24: ='3. Assumptions'!D10*'3. Assumptions'!D9*F14 -> 0.026046734 | G24: ='3. Assumptions'!D10*'3. Assumptions'!D10*G14 -> 0.036100022 | H24: ='3. Assumptions'!D10*'3. Assumptions'!D11*H14 -> 0.04425498
A25: Small Cap Mutual Fund | B25: ='3. Assumptions'!D11*'3. Assumptions'!D5*B15 -> -2.3272973e-08 | C25: ='3. Assumptions'!D11*'3. Assumptions'!D6*C15 -> -1.5764569e-08 | D25: ='3. Assumptions'!D11*'3. Assumptions'!D7*D15 -> 9.0179168e-09 | E25: ='3. Assumptions'!D11*'3. Assumptions'!D8*E15 -> 0.0032429765 | F25: ='3. Assumptions'!D11*'3. Assumptions'!D9*F15 -> 0.031410245 | G25: ='3. Assumptions'!D11*'3. Assumptions'!D10*G15 -> 0.04425498 | H25: ='3. Assumptions'!D11*'3. Assumptions'!D11*H15 -> 0.055225085
A27: Expected return per asset (from sheet 3) | B27: ='3. Assumptions'!C5 -> 0.055239832 | C27: ='3. Assumptions'!C6 -> 0.070752542 | D27: ='3. Assumptions'!C7 -> 0.096267592 | E27: ='3. Assumptions'!C8 -> 0.12128234 | F27: ='3. Assumptions'!C9 -> 0.14066184 | G27: ='3. Assumptions'!C10 -> 0.1453984 | H27: ='3. Assumptions'!C11 -> 0.12246789
A29: SOLVED weights (Mean-Variance-Optimal, Moderate / Medium-horizon) - see sheet 1 for why these are a documented input, not a formula
A30: Weight | B30: 0 | C30: 0.154178 | D30: 0.095822 | E30: 0.2 | F30: 0.35 | G30: 0.2 | H30: 0
A31: Check: weights sum to | B31: =SUM(B30:H30) -> 1
A32: Weight outer-product (w_i x w_j)
B33: =B30*B30 -> 0 | C33: =B30*C30 -> 0 | D33: =B30*D30 -> 0 | E33: =B30*E30 -> 0 | F33: =B30*F30 -> 0 | G33: =B30*G30 -> 0 | H33: =B30*H30 -> 0
B34: =C30*B30 -> 0 | C34: =C30*C30 -> 0.023770856 | D34: =C30*D30 -> 0.014773644 | E34: =C30*E30 -> 0.0308356 | F34: =C30*F30 -> 0.0539623 | G34: =C30*G30 -> 0.0308356 | H34: =C30*H30 -> 0
B35: =D30*B30 -> 0 | C35: =D30*C30 -> 0.014773644 | D35: =D30*D30 -> 0.0091818557 | E35: =D30*E30 -> 0.0191644 | F35: =D30*F30 -> 0.0335377 | G35: =D30*G30 -> 0.0191644 | H35: =D30*H30 -> 0
B36: =E30*B30 -> 0 | C36: =E30*C30 -> 0.0308356 | D36: =E30*D30 -> 0.0191644 | E36: =E30*E30 -> 0.04 | F36: =E30*F30 -> 0.07 | G36: =E30*G30 -> 0.04 | H36: =E30*H30 -> 0
B37: =F30*B30 -> 0 | C37: =F30*C30 -> 0.0539623 | D37: =F30*D30 -> 0.0335377 | E37: =F30*E30 -> 0.07 | F37: =F30*F30 -> 0.1225 | G37: =F30*G30 -> 0.07 | H37: =F30*H30 -> 0
B38: =G30*B30 -> 0 | C38: =G30*C30 -> 0.0308356 | D38: =G30*D30 -> 0.0191644 | E38: =G30*E30 -> 0.04 | F38: =G30*F30 -> 0.07 | G38: =G30*G30 -> 0.04 | H38: =G30*H30 -> 0
B39: =H30*B30 -> 0 | C39: =H30*C30 -> 0 | D39: =H30*D30 -> 0 | E39: =H30*E30 -> 0 | F39: =H30*F30 -> 0 | G39: =H30*G30 -> 0 | H39: =H30*H30 -> 0
A40: Portfolio expected return (SUMPRODUCT weights x returns) | B40: =SUMPRODUCT(B30:H30,B27:H27) -> 0.12270083
A41: Portfolio variance (SUMPRODUCT outer-product x covariance) | B41: =SUMPRODUCT(B33:H39,B19:H25) -> 0.0093950906
A42: Portfolio volatility (= SQRT(variance)) | B42: =SQRT(B41) -> 0.096928275
A43: Sharpe ratio (return - risk-free) / volatility | B43: =(B40-'3. Assumptions'!B27)/B42 -> 0.71909698
A44: MVO objective (return - 0.5 x lambda x variance) <- HIGHER IS BETTER | B44: =B40-0.5*'4. Risk & Portfolio Rules'!C5*B41 -> 0.10625942
A46: Comparison: equal-weight portfolio (1/7 each)
...

Sheet 6. Portfolio Construction
A1: Solved Portfolio Weights - all (time-horizon x risk-profile) combinations
A2: Solved by the same Python Mean-Variance-Optimization engine as the app (scipy.optimize, SLSQP), using the covariance matrix and per-asset/horizon caps from sheets 3-5. See sheet 5 for a fully live-formula worked verification of one of these cases (Moderate / Medium).
A4: Short-term horizon
A5: Profile | B5: Liquid Fund | C5: Debt Fund | D5: Gold | E5: Real Estate | F5: Large Cap Mutual Fund | G5: Mid Cap Mutual Fund | H5: Small Cap Mutual Fund
A6: Conservative | B6: 0 | C6: 0.641374 | D6: 0.008626 | E6: 0.2 | F6: 0.117774 | G6: 0.032226 | H6: 0
A7: Moderate | B7: 0 | C7: 0.540452 | D7: 0.109548 | E7: 0.2 | F7: 0.077818 | G7: 0.072182 | H7: 0
A8: Aggressive | B8: 0 | C8: 0.45 | D8: 0.2 | E8: 0.2 | F8: 0 | G8: 0.15 | H8: 0
A10: Medium-term horizon
A11: Profile | B11: Liquid Fund | C11: Debt Fund | D11: Gold | E11: Real Estate | F11: Large Cap Mutual Fund | G11: Mid Cap Mutual Fund | H11: Small Cap Mutual Fund
A12: Conservative | B12: 0 | C12: 0.425605 | D12: 0.001647 | E12: 0.2 | F12: 0.315579 | G12: 0.057169 | H12: 0
A13: Moderate | B13: 0 | C13: 0.154178 | D13: 0.095822 | E13: 0.2 | F13: 0.35 | G13: 0.2 | H13: 0
A14: Aggressive | B14: 0 | C14: 0.05 | D14: 0.2 | E14: 0.2 | F14: 0.300693 | G14: 0.249307 | H14: 0
A16: Long-term horizon
A17: Profile | B17: Liquid Fund | C17: Debt Fund | D17: Gold | E17: Real Estate | F17: Large Cap Mutual Fund | G17: Mid Cap Mutual Fund | H17: Small Cap Mutual Fund
A18: Conservative | B18: 0 | C18: 0.425605 | D18: 0.001647 | E18: 0.2 | F18: 0.315579 | G18: 0.057169 | H18: 0
A19: Moderate | B19: 0 | C19: 0.010784 | D19: 0.089216 | E19: 0.2 | F19: 0.35 | G19: 0.35 | H19: 0
A20: Aggressive | B20: 0 | C20: 0 | D20: 0 | E20: 0.2 | F20: 0.35 | G20: 0.35 | H20: 0.1
A23: Combining existing investments with new money
A24: The client's existing holdings (5 categories) are combined with new money so the OVERALL portfolio - not just the new contribution - moves toward the target mix. The split of new money across the 5 categories is solved (a small quadratic program minimising the combined portfolio's deviation from the target mix); the combination arithmetic itself is a plain weighted average, shown live below with the worked example's numbers.
A26: Category | B26: Existing (Rs) | C26: New money (Rs) | D26: Combined (Rs) | E26: Combined mix
A27: Liquid / Cash | B27: 100000 | C27: 0 | D27: =B27+C27 -> 100000 | E27: =D27/SUM($D$27:$D$31) -> 0.29850746
A28: Debt / Fixed Income | B28: 50000 | C28: 0 | D28: =B28+C28 -> 50000 | E28: =D28/SUM($D$27:$D$31) -> 0.14925373
A29: Gold | B29: 20000 | C29: 0 | D29: =B29+C29 -> 20000 | E29: =D29/SUM($D$27:$D$31) -> 0.059701493
A30: Real Estate | B30: 0 | C30: 15000 | D30: =B30+C30 -> 15000 | E30: =D30/SUM($D$27:$D$31) -> 0.044776119
A31: Mutual Funds (equity) | B31: 150000 | C31: 0 | D31: =B31+C31 -> 150000 | E31: =D31/SUM($D$27:$D$31) -> 0.44776119
A32: Total | B32: =SUM(B27:B31) -> 320000 | C32: =SUM(C27:C31) -> 15000 | D32: =SUM(D27:D31) -> 335000
A34: Edit the Existing/New-money columns above and the Combined mix recalculates live - this is exactly what the app's 'existing vs combined mix' display shows.

Sheet 7. Worked Example
A1: Worked Example - one client, computed end-to-end (matches the app for the same inputs)
A3: 1. Client inputs
A4: Age | B4: 28
A5: Dependents | B5: 1
A6: Has retirement goal (age 60) | B6: Yes
A7: Retirement age | B7: 60
A8: Location tier | B8: Tier 1 (metro)
A9: Monthly income band | B9: Rs 1,00,000 - 2,00,000
A10: Vehicle | B10: Entry-level car
A11: Employment | B11: Salaried
A12: Housing situation | B12: Renting
A13: Monthly EMI / loan payments (Rs) | B13: 5000
A14: High-interest debt? | B14: No
A15: Existing - Liquid/Cash (Rs) | B15: 100000
A16: Existing - Debt/Fixed Income (Rs) | B16: 50000
A17: Existing - Gold (Rs) | B17: 20000
A18: Existing - Real Estate (Rs) | B18: 0
A19: Existing - Mutual Funds equity (Rs) | B19: 150000
A20: Emergency savings already set aside (Rs) | B20: 30000
A21: Investment mode | B21: SIP (monthly)
A22: SIP amount (Rs/month) | B22: 15000
A23: Stated risk appetite | B23: Moderate
A24: Risk quiz average score (of 10) | B24: 6
A26: 2. Estimated income & expenses (from the inputs above, not typed in)
A27: Monthly income (looked up from the income-band table) | B27: =INDEX('3. Assumptions'!B34:B43,MATCH(B9,'3. Assumptions'!A34:A43,0)) -> 150000
A28: Base expense ratio (looked up by the same income band) | B28: =INDEX('3. Assumptions'!B47:B56,MATCH(B9,'3. Assumptions'!A34:A43,0)) -> 0.65
A29: + per-dependent add-on | B29: =B5*'3. Assumptions'!B59 -> 0.04
A30: + housing-situation load | B30: =INDEX('3. Assumptions'!B64:B67,MATCH(B12,'3. Assumptions'!A64:A67,0)) -> 0.18
A31: + vehicle lifestyle nudge | B31: =INDEX('3. Assumptions'!B71:B75,MATCH(B10,'3. Assumptions'!A71:A75,0)) -> 0.03
A32: Raw expense ratio (before city index / cap) | B32: =B28+B29+B30+B31 -> 0.9
A33: City cost-of-living index | B33: =INDEX('3. Assumptions'!B79:B81,MATCH(B8,'3. Assumptions'!A79:A81,0)) -> 1.2
A34: Final expense ratio (raw x city index, capped to floor/cap) | B34: =MAX('3. Assumptions'!B60,MIN('3. Assumptions'!C60,B32*B33)) -> 0.95
A35: Estimated monthly expenses | B35: =B27*B34 -> 142500
A37: 3. Goals (today's cost inflated to the goal date)
A38: Goal | B38: Goal type | C38: Cost today (Rs) | D38: Years to go | E38: Inflation (looked up) | F38: Target (future Rs)
A39: Bali trip (Southeast Asia) | B39: Vacation | C39: 150000 | D39: 2 | E39: =INDEX('3. Assumptions'!B16:B21,MATCH(B39,'3. Assumptions'!A16:A21,0)) -> 0.06 | F39: =C39*(1+E39)^D39 -> 168540
A40: Child education | B40: Education | C40: 2000000 | D40: 15 | E40: =INDEX('3. Assumptions'!B16:B21,MATCH(B40,'3. Assumptions'!A16:A21,0)) -> 0.08 | F40: =C40*(1+E40)^D40 -> 6344338.2
A41: Retirement | B41: Others | C41: 42750000 | D41: 32 | E41: =INDEX('3. Assumptions'!B16:B21,MATCH(B41,'3. Assumptions'!A16:A21,0)) -> 0.05 | F41: =C41*(1+E41)^D41 -> 2.0370125e+08
A42: Retirement target = (monthly expenses x 12 x retirement multiple) x (1+general inflation)^years to retirement - computed below since it depends on the expense figure above.
A43: Retirement (today's annual-expense-based corpus, inflated) | F43: =B35*12*'3. Assumptions'!B28*(1+'3. Assumptions'!B25)^(B7-B4) -> 2.0370125e+08
...
